<?xml version="1.0" ?>
<!-- =================================================================================== -->
<!-- |    This document was autogenerated by xacro from kuka_lwr_arm.urdf.xacro        | -->
<!-- |    EDITING THIS FILE BY HAND IS NOT RECOMMENDED                                 | -->
<!-- |                                                                                 | -->
<!-- |    I edited this by hand anyway - Alon Flor                                     | -->
<!-- =================================================================================== -->
<robot name="kuka_lwr">
  <!-- right is either 1 (for right arm) or -1 (for left arm) -->
  <link name="calib_kuka_arm_base_link">
    <inertial>
      <mass value="0"/>
      <!-- static base, disable dynamics for this link -->
      <origin rpy="0 0 0" xyz="0 0 0.055"/>
      <inertia ixx="0.00381666666667" ixy="0" ixz="0" iyy="0.0036" iyz="0" izz="0.00381666666667"/>
    </inertial>
    <visual>
      <origin rpy="0 0 0" xyz="0 0 0"/>
      <geometry>
        <mesh filename="meshes_arm/arm_base.stl"/>
      </geometry>
      <material name="Orange"/>
    </visual>
    <collision>
      <origin rpy="0 0 0" xyz="0 0 0"/>
      <geometry>
        <mesh filename="meshes_arm/convex/arm_base_convex.stl"/>
      </geometry>
    </collision>
  </link>
  <joint name="kuka_arm_0_joint" type="revolute">
    <origin rpy="0 0 0" xyz="0 0 0.11"/>
    <axis xyz="0 0 1"/>
    <limit effort="204" lower="-2.96705972839" upper="2.96705972839" velocity="1.91986217719"/>
    <dynamics damping="0.1"/>
    <parent link="calib_kuka_arm_base_link"/>
    <child link="kuka_arm_1_link"/>
  </joint>
  <link name="kuka_arm_1_link">
    <inertial>
      <mass value="2.0"/>
      <origin rpy="0 0 0" xyz="0 0.04 0.130"/>
      <inertia ixx="0.0136666666667" ixy="0" ixz="0" iyy="0.0118666666667" iyz="0" izz="0.003"/>
    </inertial>
    <visual>
      <origin rpy="0 0 3.14159265359" xyz="0 0 0"/>
      <geometry>
        <mesh filename="meshes_arm/arm_segment_a.stl"/>
      </geometry>
      <material name="Orange"/>
    </visual>
    <collision>
      <origin rpy="0 0 3.14159265359" xyz="0 0 0"/>
      <geometry>
        <mesh filename="meshes_arm/convex/arm_segment_a_convex.stl"/>
      </geometry>
    </collision>
  </link>
  <transmission name="kuka_arm_0_trans" type="pr2_mechanism_model/SimpleTransmission">
    <actuator name="kuka_arm_0_motor"/>
    <joint name="kuka_arm_0_joint"/>
    <mechanicalReduction>1.0</mechanicalReduction>
  </transmission>
  <joint name="kuka_arm_1_joint" type="revolute">
    <origin rpy="0 0 0" xyz="0 0 0.20"/>
    <axis xyz="0 -1 0"/>
    <!--limit lower="${-120 * M_PI / 180}" upper="${120 * M_PI / 180}"
             effort="306" velocity="${arm_velocity_scale_factor * 110 * M_PI / 180}" /-->
    <!-- nalt: Reduced limits to avoid contact with table - kinda hacky, should not be done here -->
    <limit effort="306" lower="-1.57079632679" upper="1.57079632679" velocity="1.91986217719"/>
    <dynamics damping="0.1"/>
    <parent link="kuka_arm_1_link"/>
    <child link="kuka_arm_2_link"/>
  </joint>
  <link name="kuka_arm_2_link">
    <inertial>
      <mass value="2.0"/>
      <origin rpy="0 0 0" xyz="0 -0.04 0.07"/>
      <inertia ixx="0.0136666666667" ixy="0" ixz="0" iyy="0.0118666666667" iyz="0" izz="0.003"/>
    </inertial>
    <visual>
      <origin rpy="3.14159265359 0 3.14159265359" xyz="0 0 0.2"/>
      <geometry>
        <mesh filename="meshes_arm/arm_segment_b.stl"/>
      </geometry>
      <material name="Orange"/>
    </visual>
    <collision>
      <origin rpy="3.14159265359 0 3.14159265359" xyz="0 0 0.2"/>
      <geometry>
        <mesh filename="meshes_arm/convex/arm_segment_b_convex.stl"/>
      </geometry>
    </collision>
  </link>
  <transmission name="kuka_arm_1_trans" type="pr2_mechanism_model/SimpleTransmission">
    <actuator name="kuka_arm_1_motor"/>
    <joint name="kuka_arm_1_joint"/>
    <mechanicalReduction>1.0</mechanicalReduction>
  </transmission>
  <joint name="kuka_arm_2_joint" type="revolute">
    <origin rpy="0 0 0" xyz="0 0 0.20"/>
    <axis xyz="0 0 1"/>
    <limit effort="204" lower="-2.96705972839" upper="2.96705972839" velocity="2.26892802759"/>
    <dynamics damping="0.1"/>
    <parent link="kuka_arm_2_link"/>
    <child link="kuka_arm_3_link"/>
  </joint>
  <link name="kuka_arm_3_link">
    <inertial>
      <mass value="2.0"/>
      <origin rpy="0 0 0" xyz="0 -0.04 0.130"/>
      <inertia ixx="0.0136666666667" ixy="0" ixz="0" iyy="0.0118666666667" iyz="0" izz="0.003"/>
    </inertial>
    <visual>
      <origin rpy="0 0 0" xyz="0 0 0"/>
      <geometry>
        <mesh filename="meshes_arm/arm_segment_a.stl"/>
      </geometry>
      <material name="Orange"/>
    </visual>
    <collision>
      <origin rpy="0 0 0" xyz="0 0 0"/>
      <geometry>
        <mesh filename="meshes_arm/convex/arm_segment_a_convex.stl"/>
      </geometry>
    </collision>
  </link>
  <transmission name="kuka_arm_2_trans" type="pr2_mechanism_model/SimpleTransmission">
    <actuator name="kuka_arm_2_motor"/>
    <joint name="kuka_arm_2_joint"/>
    <mechanicalReduction>1.0</mechanicalReduction>
  </transmission>
  <joint name="kuka_arm_3_joint" type="revolute">
    <origin rpy="0 0 0" xyz="0 0 0.20"/>
    <axis xyz="0 1 0"/>
    <limit effort="306" lower="-2.09439510239" upper="2.09439510239" velocity="2.26892802759"/>
    <dynamics damping="0.1"/>
    <parent link="kuka_arm_3_link"/>
    <child link="kuka_arm_4_link"/>
  </joint>
  <link name="kuka_arm_4_link">
    <inertial>
      <mass value="2.0"/>
      <origin rpy="0 0 0" xyz="0 0.04 0.07"/>
      <inertia ixx="0.0136666666667" ixy="0" ixz="0" iyy="0.0118666666667" iyz="0" izz="0.003"/>
    </inertial>
    <visual>
      <origin rpy="0 3.14159265359 3.14159265359" xyz="0 0 0.2"/>
      <geometry>
        <mesh filename="meshes_arm/arm_segment_b.stl"/>
      </geometry>
      <material name="Orange"/>
    </visual>
    <collision>
      <origin rpy="0 3.14159265359 3.14159265359" xyz="0 0 0.2"/>
      <geometry>
        <mesh filename="meshes_arm/convex/arm_segment_b_convex.stl"/>
      </geometry>
    </collision>
  </link>
  <transmission name="kuka_arm_3_trans" type="pr2_mechanism_model/SimpleTransmission">
    <actuator name="kuka_arm_3_motor"/>
    <joint name="kuka_arm_3_joint"/>
    <mechanicalReduction>1.0</mechanicalReduction>
  </transmission>
  <joint name="kuka_arm_4_joint" type="revolute">
    <origin rpy="0 0 0" xyz="0 0 0.20"/>
    <axis xyz="0 0 1"/>
    <limit effort="204" lower="-2.96705972839" upper="2.96705972839" velocity="2.26892802759"/>
    <dynamics damping="0.1"/>
    <parent link="kuka_arm_4_link"/>
    <child link="kuka_arm_5_link"/>
  </joint>
  <link name="kuka_arm_5_link">
    <inertial>
      <mass value="2.0"/>
      <origin rpy="0 0 0" xyz="0 0.02 0.124"/>
      <inertia ixx="0.0126506666667" ixy="0" ixz="0" iyy="0.0108506666667" iyz="0" izz="0.003"/>
    </inertial>
    <visual>
      <origin rpy="0 0 3.14159265359" xyz="0 0 0"/>
      <geometry name="kuka_arm_5_geom">
        <mesh filename="meshes_arm/arm_segment_last.stl"/>
      </geometry>
      <material name="Orange"/>
    </visual>
    <collision>
      <origin rpy="0 0 3.14159265359" xyz="0 0 0"/>
      <geometry>
        <mesh filename="meshes_arm/convex/arm_segment_last_convex.stl"/>
      </geometry>
    </collision>
  </link>
  <transmission name="kuka_arm_4_trans" type="pr2_mechanism_model/SimpleTransmission">
    <actuator name="kuka_arm_4_motor"/>
    <joint name="kuka_arm_4_joint"/>
    <mechanicalReduction>1.0</mechanicalReduction>
  </transmission>
  <joint name="kuka_arm_5_joint" type="revolute">
    <origin rpy="0 0 0" xyz="0 0 0.19"/>
    <axis xyz="0 -1 0"/>
    <limit effort="306" lower="-2.09439510239" upper="2.09439510239" velocity="3.14159265359"/>
    <dynamics damping="0.1"/>
    <parent link="kuka_arm_5_link"/>
    <child link="kuka_arm_6_link"/>
  </joint>
  <link name="kuka_arm_6_link">
    <inertial>
      <mass value="2.0"/>
      <origin rpy="0 0 0" xyz="0 0 0"/>
      <inertia ixx="0.00520833333333" ixy="0" ixz="0" iyy="0.00520833333333" iyz="0" izz="0.00520833333333"/>
    </inertial>
    <visual>
      <origin rpy="0 0 3.14159265359" xyz="0 0 0"/>
      <geometry>
        <mesh filename="meshes_arm/arm_wrist.stl"/>
      </geometry>
      <material name="Grey"/>
    </visual>
    <collision>
      <origin rpy="0 0 3.14159265359" xyz="0 0 0"/>
      <geometry>
        <mesh filename="meshes_arm/convex/arm_wrist_convex.stl"/>
      </geometry>
    </collision>
  </link>
  <transmission name="kuka_arm_5_trans" type="pr2_mechanism_model/SimpleTransmission">
    <actuator name="kuka_arm_5_motor"/>
    <joint name="kuka_arm_5_joint"/>
    <mechanicalReduction>1.0</mechanicalReduction>
  </transmission>
  <joint name="kuka_arm_6_joint" type="revolute">
    <origin rpy="0 0 0" xyz="0 0 0.078"/>
    <axis xyz="0 0 1"/>
    <limit effort="204" lower="-2.96705972839" upper="2.96705972839" velocity="3.14159265359"/>
    <dynamics damping="0.1"/>
    <parent link="kuka_arm_6_link"/>
    <child link="kuka_arm_7_link"/>
  </joint>
  <link name="kuka_arm_7_link">
    <inertial>
      <mass value="2.0"/>
      <origin xyz="0 0 0"/>
      <inertia ixx="0.000833333333333" ixy="0" ixz="0" iyy="0.000833333333333" iyz="0" izz="0.000833333333333"/>
    </inertial>
    <visual>
      <origin rpy="0 0 3.14159265359" xyz="0 0 0"/>
      <geometry>
        <mesh filename="meshes_arm/arm_flanche.stl"/>
      </geometry>
      <material name="Grey"/>
    </visual>
    <collision>
      <origin rpy="0 0 3.14159265359" xyz="0 0 0"/>
      <geometry>
        <mesh filename="meshes_arm/convex/arm_flanche_convex.stl"/>
      </geometry>
    </collision>
  </link>
  <transmission name="kuka_arm_6_trans" type="pr2_mechanism_model/SimpleTransmission">
    <actuator name="kuka_arm_6_motor"/>
    <joint name="kuka_arm_6_joint"/>
    <mechanicalReduction>1.0</mechanicalReduction>
  </transmission>
  <link name="finger_1_link_0">
    <visual>
      <origin rpy="0 0 0" xyz="0.020 0 0"/>
      <geometry>
        <mesh filename="visual/link_0.STL"/>
      </geometry>
      <material name="green">
        <color rgba="0 1 0 1"/>
      </material>
    </visual>
    <collision>
      <origin rpy="0 3.1416 -1.57" xyz="-0.0455 0.0414 0.036"/>
      <geometry>
        <mesh filename="collision/link_0.STL"/>
      </geometry>
      <material name="yellow">
        <color rgba="0 1 1 1"/>
      </material>
    </collision>
    <inertial>
      <origin rpy="0 0 0" xyz="0 0 0"/>
      <mass value="0.05"/>
      <inertia ixx="0.01" ixy="-0.00002" ixz="0.00001" iyy="0.0008" iyz="0" izz="0.001"/>
    </inertial>
  </link>
  <link name="finger_1_link_1">
    <visual>
      <origin rpy="0 0 -0.52" xyz="0.050 -.028 0"/>
      <geometry>
        <mesh filename="visual/link_1.STL"/>
      </geometry>
      <material name="green"/>
    </visual>
    <collision>
      <origin rpy="0 0 -0.52" xyz="0.050 -.028 0"/>
      <geometry>
        <mesh filename="collision/link_1.STL"/>
      </geometry>
      <material name="yellow"/>
    </collision>
    <inertial>
      <origin rpy="0 0 0" xyz="0 0 0"/>
      <mass value="0.15"/>
      <inertia ixx="0.001859" ixy="-0.000376" ixz="0.000028" iyy="0.012756" iyz="0" izz="0.0024"/>
    </inertial>
  </link>
  <link name="finger_1_link_2">
    <!--
			NOTE: This link has an offset in the z-direction based on the models that were
			used to generate grap-it poses.  With the offset below the model appears visually
			correct, but it is suspect.
			-->
    <visual>
      <origin rpy="0 0 0" xyz="0.039 0 0.0075"/>
      <geometry>
        <mesh filename="visual/link_2.STL"/>
      </geometry>
      <material name="green"/>
    </visual>
    <collision>
      <origin rpy="0 0 0" xyz="0.039 0 0.0075"/>
      <geometry>
        <mesh filename="collision/link_2.STL"/>
      </geometry>
      <material name="yellow"/>
    </collision>
    <inertial>
      <origin rpy="0 0 0" xyz="0 0 0"/>
      <mass value="0.15"/>
      <inertia ixx="0.001859" ixy="-0.000376" ixz="0.000028" iyy="0.012756" iyz="0" izz="0.0024"/>
    </inertial>
  </link>
  <link name="finger_1_link_3">
    <visual>
      <origin rpy="0 0 0.52" xyz="0 0 0"/>
      <geometry>
        <mesh filename="visual/link_3.STL"/>
      </geometry>
      <material name="green"/>
    </visual>
    <collision>
      <origin rpy="0 0 0.52" xyz="0 0 0"/>
      <geometry>
        <mesh filename="collision/link_3.STL"/>
      </geometry>
      <material name="yellow"/>
    </collision>
    <inertial>
      <origin rpy="0 0 0" xyz="0 0 0"/>
      <mass value="0.05"/>
      <inertia ixx="0.001239" ixy="-0.000251" ixz="0.000019" iyy="0.00085" iyz="0" izz="0.001632"/>
    </inertial>
  </link>
  <joint name="finger_1_joint_1" type="fixed">
    <parent link="finger_1_link_0"/>
    <child link="finger_1_link_1"/>
    <!-- axis xyz="0 0 1"/ -->
    <origin rpy="0 0 0.4" xyz="0.020 0 0"/>
    <!-- origin rpy="0 0 0" xyz="0.020 0 0"/ -->
    <!-- limit effort="100" lower="0" upper="3.1416" velocity="100"/ -->
  </joint>
  <joint name="finger_1_joint_2" type="fixed">
    <parent link="finger_1_link_1"/>
    <child link="finger_1_link_2"/>
    <!-- axis xyz="0 0 1"/ -->
    <origin rpy="0 0 0.52" xyz="0.050 -.028 0"/>
    <!-- origin rpy="0 0 -0.52" xyz="0.050 -.028 0"/ -->
    <!-- limit effort="100" lower="0" upper="3.1416" velocity="100"/ -->
  </joint>
  <joint name="finger_1_joint_3" type="fixed">
    <parent link="finger_1_link_2"/>
    <child link="finger_1_link_3"/>
    <!-- axis xyz="0 0 1"/ -->
    <origin rpy="0 0 0" xyz="0.039 0 0"/>
    <!-- limit effort="100" lower="0" upper="3.1416" velocity="100"/ -->
  </joint>
  <link name="finger_2_link_0">
    <visual>
      <origin rpy="0 0 0" xyz="0.020 0 0"/>
      <geometry>
        <mesh filename="visual/link_0.STL"/>
      </geometry>
      <material name="green">
        <color rgba="0 1 0 1"/>
      </material>
    </visual>
    <collision>
      <origin rpy="0 3.1416 -1.57" xyz="-0.0455 0.0414 0.036"/>
      <geometry>
        <mesh filename="collision/link_0.STL"/>
      </geometry>
      <material name="yellow">
        <color rgba="0 1 1 1"/>
      </material>
    </collision>
    <inertial>
      <origin rpy="0 0 0" xyz="0 0 0"/>
      <mass value="0.05"/>
      <inertia ixx="0.01" ixy="-0.00002" ixz="0.00001" iyy="0.0008" iyz="0" izz="0.001"/>
    </inertial>
  </link>
  <link name="finger_2_link_1">
    <visual>
      <origin rpy="0 0 -0.52" xyz="0.050 -.028 0"/>
      <geometry>
        <mesh filename="visual/link_1.STL"/>
      </geometry>
      <material name="green"/>
    </visual>
    <collision>
      <origin rpy="0 0 -0.52" xyz="0.050 -.028 0"/>
      <geometry>
        <mesh filename="collision/link_1.STL"/>
      </geometry>
      <material name="yellow"/>
    </collision>
    <inertial>
      <origin rpy="0 0 0" xyz="0 0 0"/>
      <mass value="0.15"/>
      <inertia ixx="0.001859" ixy="-0.000376" ixz="0.000028" iyy="0.012756" iyz="0" izz="0.0024"/>
    </inertial>
  </link>
  <link name="finger_2_link_2">
    <!--
			NOTE: This link has an offset in the z-direction based on the models that were
			used to generate grap-it poses.  With the offset below the model appears visually
			correct, but it is suspect.
			-->
    <visual>
      <origin rpy="0 0 0" xyz="0.039 0 0.0075"/>
      <geometry>
        <mesh filename="visual/link_2.STL"/>
      </geometry>
      <material name="green"/>
    </visual>
    <collision>
      <origin rpy="0 0 0" xyz="0.039 0 0.0075"/>
      <geometry>
        <mesh filename="collision/link_2.STL"/>
      </geometry>
      <material name="yellow"/>
    </collision>
    <inertial>
      <origin rpy="0 0 0" xyz="0 0 0"/>
      <mass value="0.15"/>
      <inertia ixx="0.001859" ixy="-0.000376" ixz="0.000028" iyy="0.012756" iyz="0" izz="0.0024"/>
    </inertial>
  </link>
  <link name="finger_2_link_3">
    <visual>
      <origin rpy="0 0 0.52" xyz="0 0 0"/>
      <geometry>
        <mesh filename="visual/link_3.STL"/>
      </geometry>
      <material name="green"/>
    </visual>
    <collision>
      <origin rpy="0 0 0.52" xyz="0 0 0"/>
      <geometry>
        <mesh filename="collision/link_3.STL"/>
      </geometry>
      <material name="yellow"/>
    </collision>
    <inertial>
      <origin rpy="0 0 0" xyz="0 0 0"/>
      <mass value="0.05"/>
      <inertia ixx="0.001239" ixy="-0.000251" ixz="0.000019" iyy="0.00085" iyz="0" izz="0.001632"/>
    </inertial>
  </link>
  <joint name="finger_2_joint_1" type="fixed">
    <parent link="finger_2_link_0"/>
    <child link="finger_2_link_1"/>
    <!-- axis xyz="0 0 1"/ -->
    <origin rpy="0 0 0.4" xyz="0.020 0 0"/>
    <!-- limit effort="100" lower="0" upper="3.1416" velocity="100"/ -->
  </joint>
  <joint name="finger_2_joint_2" type="fixed">
    <parent link="finger_2_link_1"/>
    <child link="finger_2_link_2"/>
    <!-- axis xyz="0 0 1"/ -->
    <origin rpy="0 0 0.52" xyz="0.050 -.028 0"/>
    <!-- origin rpy="0 0 -0.52" xyz="0.050 -.028 0"/ -->
    <!-- limit effort="100" lower="0" upper="3.1416" velocity="100"/ -->
  </joint>
  <joint name="finger_2_joint_3" type="fixed">
    <parent link="finger_2_link_2"/>
    <child link="finger_2_link_3"/>
    <!-- axis xyz="0 0 1"/ -->
    <origin rpy="0 0 0" xyz="0.039 0 0"/>
    <!-- limit effort="100" lower="0" upper="3.1416" velocity="100"/ -->
  </joint>
  <link name="finger_middle_link_0">
    <visual>
      <origin rpy="0 0 0" xyz="0.020 0 0"/>
      <geometry>
        <mesh filename="visual/link_0.STL"/>
      </geometry>
      <material name="green">
        <color rgba="0 1 0 1"/>
      </material>
    </visual>
    <collision>
      <origin rpy="0 3.1416 -1.57" xyz="-0.0455 0.0414 0.036"/>
      <geometry>
        <mesh filename="collision/link_0.STL"/>
      </geometry>
      <material name="yellow">
        <color rgba="0 1 1 1"/>
      </material>
    </collision>
    <inertial>
      <origin rpy="0 0 0" xyz="0 0 0"/>
      <mass value="0.05"/>
      <inertia ixx="0.01" ixy="-0.00002" ixz="0.00001" iyy="0.0008" iyz="0" izz="0.001"/>
    </inertial>
  </link>
  <link name="finger_middle_link_1">
    <visual>
      <origin rpy="0 0 -0.52" xyz="0.050 -.028 0"/>
      <geometry>
        <mesh filename="visual/link_1.STL"/>
      </geometry>
      <material name="green"/>
    </visual>
    <collision>
      <origin rpy="0 0 -0.52" xyz="0.050 -.028 0"/>
      <geometry>
        <mesh filename="collision/link_1.STL"/>
      </geometry>
      <material name="yellow"/>
    </collision>
    <inertial>
      <origin rpy="0 0 0" xyz="0 0 0"/>
      <mass value="0.15"/>
      <inertia ixx="0.001859" ixy="-0.000376" ixz="0.000028" iyy="0.012756" iyz="0" izz="0.0024"/>
    </inertial>
  </link>
  <link name="finger_middle_link_2">
    <!--
			NOTE: This link has an offset in the z-direction based on the models that were
			used to generate grap-it poses.  With the offset below the model appears visually
			correct, but it is suspect.
			-->
    <visual>
      <origin rpy="0 0 0" xyz="0.039 0 0.0075"/>
      <geometry>
        <mesh filename="visual/link_2.STL"/>
      </geometry>
      <material name="green"/>
    </visual>
    <collision>
      <origin rpy="0 0 0" xyz="0.039 0 0.0075"/>
      <geometry>
        <mesh filename="collision/link_2.STL"/>
      </geometry>
      <material name="yellow"/>
    </collision>
    <inertial>
      <origin rpy="0 0 0" xyz="0 0 0"/>
      <mass value="0.15"/>
      <inertia ixx="0.001859" ixy="-0.000376" ixz="0.000028" iyy="0.012756" iyz="0" izz="0.0024"/>
    </inertial>
  </link>
  <link name="finger_middle_link_3">
    <visual>
      <origin rpy="0 0 0.52" xyz="0 0 0"/>
      <geometry>
        <mesh filename="visual/link_3.STL"/>
      </geometry>
      <material name="green"/>
    </visual>
    <collision>
      <origin rpy="0 0 0.52" xyz="0 0 0"/>
      <geometry>
        <mesh filename="collision/link_3.STL"/>
      </geometry>
      <material name="yellow"/>
    </collision>
    <inertial>
      <origin rpy="0 0 0" xyz="0 0 0"/>
      <mass value="0.05"/>
      <inertia ixx="0.001239" ixy="-0.000251" ixz="0.000019" iyy="0.00085" iyz="0" izz="0.001632"/>
    </inertial>
  </link>
  <joint name="finger_middle_joint_1" type="fixed">
    <parent link="finger_middle_link_0"/>
    <child link="finger_middle_link_1"/>
    <!-- axis xyz="0 0 1"/ -->
    <origin rpy="0 0 0" xyz="0.020 0 0"/>
    <!-- limit effort="100" lower="0" upper="3.1416" velocity="100"/ -->
  </joint>
  <joint name="finger_middle_joint_2" type="fixed">
    <parent link="finger_middle_link_1"/>
    <child link="finger_middle_link_2"/>
    <!-- axis xyz="0 0 1"/ -->
    <origin rpy="0 0 -.7" xyz="0.050 -.028 0"/>
    <!-- origin rpy="0 0 -0.52" xyz="0.050 -.028 0"/ -->
    <!-- limit effort="100" lower="0" upper="3.1416" velocity="100"/ -->
  </joint>
  <joint name="finger_middle_joint_3" type="fixed">
    <parent link="finger_middle_link_2"/>
    <child link="finger_middle_link_3"/>
    <!-- axis xyz="0 0 1"/ -->
    <origin rpy="0 0 -.7" xyz="0.039 0 0"/>
    <!-- origin rpy="0 0 0" xyz="0.039 0 0"/ -->
    <!-- limit effort="100" lower="0" upper="3.1416" velocity="100"/ -->
  </joint>
  <link name="palm">
    <visual>
      <geometry>
        <mesh filename="visual/palm.STL"/>
      </geometry>
      <material name="green">
        <color rgba="0 1 0 1"/>
      </material>
    </visual>
    <collision>
      <geometry>
        <mesh filename="collision/palm.STL"/>
      </geometry>
      <material name="yellow">
        <color rgba="0 1 1 1"/>
      </material>
    </collision>
  </link>
  <inertial>
    <origin rpy="0 0 0" xyz="0 0 0"/>
    <mass value="1.3"/>
    <inertia ixx="0.006012" ixy="0.000079" ixz="-0.00024" iyy="0.012892" iyz="0" izz="0.002435"/>
  </inertial>
  <joint name="palm_finger_1_joint" type="fixed">
    <parent link="palm"/>
    <child link="finger_1_link_0"/>
    <!-- axis xyz="0 1 0"/ -->
    <origin rpy="0 3.1416 -2.5" xyz="-0.0455 0.0214 0.036"/>
    <!-- origin rpy="0 3.1416 -1.57" xyz="-0.0455 0.0214 0.036"/ -->
    <!-- limit effort="100" lower="-0.416" upper="0.425" velocity="100"/ -->
  </joint>
  <joint name="palm_finger_2_joint" type="fixed">
    <parent link="palm"/>
    <child link="finger_2_link_0"/>
    <!-- axis xyz="0 1 0"/ -->
    <origin rpy="0 3.1416 -2.5" xyz="-0.0455 0.0214 -0.036"/>
    <!-- origin rpy="0 3.1416 -1.57" xyz="-0.0455 0.0214 -0.036"/ -->
    <!-- limit effort="100" lower="-0.425" upper="0.416" velocity="100"/ -->
  </joint>
  <joint name="palm_finger_middle_joint" type="fixed">
    <parent link="palm"/>
    <child link="finger_middle_link_0"/>
    <!-- axis xyz="0 0 1"/ -->
    <origin rpy="0 0 2." xyz="0.0455 0.0214 0"/>
    <!-- origin rpy="0 0 1.57" xyz="0.0455 0.0214 0"/ -->
    <!-- limit effort="100" lower="-0.42" upper="0.42" velocity="100"/ -->
  </joint>
  <joint name="kuka_arm_7_joint" type="fixed">
    <origin rpy="1.57 0 0" xyz="0 0 0.00"/>
    <parent link="kuka_arm_7_link"/>
    <child link="palm"/>
  </joint>
</robot>

